{"stats": {"errors": 0, "failures": 5, "passes": 2, "skipped": 0, "encoding": "UTF-8", "total": 7}, "results": [{"classname": "index_test:TestDistance", "name": "test_avenue_distance", "time": 0.0003218650817871094, "type": "success"}, {"classname": "index_test:TestDistance", "name": "test_distance", "time": 0.0002639293670654297, "type": "failure", "errtype": "builtins.AssertionError", "message": "None != 4.123105625617661", "tb": "Traceback (most recent call last):\n  File \"/opt/conda/lib/python3.6/site-packages/unittest2/case.py\", line 67, in testPartExecutor\n    yield\n  File \"/opt/conda/lib/python3.6/site-packages/unittest2/case.py\", line 625, in run\n    testMethod()\n  File \"/home/erickalexander/calculating-distance-lab-data-science-pilot/test/index_test.py\", line 18, in test_distance\n    self.assertEqual(distance(fred, natalie), 4.123105625617661)\n  File \"/opt/conda/lib/python3.6/site-packages/unittest2/case.py\", line 836, in assertEqual\n    assertion_func(first, second, msg=msg)\n  File \"/opt/conda/lib/python3.6/site-packages/unittest2/case.py\", line 829, in _baseAssertEqual\n    raise self.failureException(msg)\nAssertionError: None != 4.123105625617661\n"}, {"classname": "index_test:TestDistance", "name": "test_distance_all", "time": 0.0007762908935546875, "type": "failure", "errtype": "builtins.AssertionError", "message": "None != [{'avenue': 1, 'distance': 4.242640687119[322 chars]: 4}]", "tb": "Traceback (most recent call last):\n  File \"/opt/conda/lib/python3.6/site-packages/unittest2/case.py\", line 67, in testPartExecutor\n    yield\n  File \"/opt/conda/lib/python3.6/site-packages/unittest2/case.py\", line 625, in run\n    testMethod()\n  File \"/home/erickalexander/calculating-distance-lab-data-science-pilot/test/index_test.py\", line 28, in test_distance_all\n    {'avenue': 5, 'distance': 4.123105625617661, 'name': 'Natalie', 'street': 4}])\n  File \"/opt/conda/lib/python3.6/site-packages/unittest2/case.py\", line 836, in assertEqual\n    assertion_func(first, second, msg=msg)\n  File \"/opt/conda/lib/python3.6/site-packages/unittest2/case.py\", line 829, in _baseAssertEqual\n    raise self.failureException(msg)\nAssertionError: None != [{'avenue': 1, 'distance': 4.242640687119[322 chars]: 4}]\n"}, {"classname": "index_test:TestDistance", "name": "test_distance_between_neighbors_squared", "time": 0.0002224445343017578, "type": "failure", "errtype": "builtins.AssertionError", "message": "None != 17", "tb": "Traceback (most recent call last):\n  File \"/opt/conda/lib/python3.6/site-packages/unittest2/case.py\", line 67, in testPartExecutor\n    yield\n  File \"/opt/conda/lib/python3.6/site-packages/unittest2/case.py\", line 625, in run\n    testMethod()\n  File \"/home/erickalexander/calculating-distance-lab-data-science-pilot/test/index_test.py\", line 15, in test_distance_between_neighbors_squared\n    self.assertEqual(distance_between_neighbors_squared(fred, natalie), 17)\n  File \"/opt/conda/lib/python3.6/site-packages/unittest2/case.py\", line 836, in assertEqual\n    assertion_func(first, second, msg=msg)\n  File \"/opt/conda/lib/python3.6/site-packages/unittest2/case.py\", line 829, in _baseAssertEqual\n    raise self.failureException(msg)\nAssertionError: None != 17\n"}, {"classname": "index_test:TestDistance", "name": "test_distance_with_neighbor", "time": 0.0003437995910644531, "type": "failure", "errtype": "builtins.AssertionError", "message": "None != {'avenue': 5, 'distance': 4.123105625617661, 'name': 'Natalie', 'street': 4}", "tb": "Traceback (most recent call last):\n  File \"/opt/conda/lib/python3.6/site-packages/unittest2/case.py\", line 67, in testPartExecutor\n    yield\n  File \"/opt/conda/lib/python3.6/site-packages/unittest2/case.py\", line 625, in run\n    testMethod()\n  File \"/home/erickalexander/calculating-distance-lab-data-science-pilot/test/index_test.py\", line 21, in test_distance_with_neighbor\n    self.assertEqual(distance_with_neighbor(fred, natalie), {'avenue': 5, 'distance': 4.123105625617661, 'name': 'Natalie', 'street': 4})\n  File \"/opt/conda/lib/python3.6/site-packages/unittest2/case.py\", line 836, in assertEqual\n    assertion_func(first, second, msg=msg)\n  File \"/opt/conda/lib/python3.6/site-packages/unittest2/case.py\", line 829, in _baseAssertEqual\n    raise self.failureException(msg)\nAssertionError: None != {'avenue': 5, 'distance': 4.123105625617661, 'name': 'Natalie', 'street': 4}\n"}, {"classname": "index_test:TestDistance", "name": "test_nearest_neighbors", "time": 0.0002052783966064453, "type": "failure", "errtype": "builtins.AssertionError", "message": "None != [{'avenue': 5, 'distance': 1.0, 'name': '[90 chars]: 6}]", "tb": "Traceback (most recent call last):\n  File \"/opt/conda/lib/python3.6/site-packages/unittest2/case.py\", line 67, in testPartExecutor\n    yield\n  File \"/opt/conda/lib/python3.6/site-packages/unittest2/case.py\", line 625, in run\n    testMethod()\n  File \"/home/erickalexander/calculating-distance-lab-data-science-pilot/test/index_test.py\", line 32, in test_nearest_neighbors\n    {'avenue': 3, 'distance': 2.23606797749979, 'name': 'Steven', 'street': 6}])\n  File \"/opt/conda/lib/python3.6/site-packages/unittest2/case.py\", line 836, in assertEqual\n    assertion_func(first, second, msg=msg)\n  File \"/opt/conda/lib/python3.6/site-packages/unittest2/case.py\", line 829, in _baseAssertEqual\n    raise self.failureException(msg)\nAssertionError: None != [{'avenue': 5, 'distance': 1.0, 'name': '[90 chars]: 6}]\n"}, {"classname": "index_test:TestDistance", "name": "test_street_distance", "time": 0.0001232624053955078, "type": "success"}]}